Workbook

Sheet Biblioteca
A1: ⚙️ BIBLIOTECA DE INGREDIENTES
A3: 🌾 GRANOS
A4: ID | B4: Nombre | C4: Código | D4: Densidad (g/ml) | E4: Tipo | F4: Notas
A5: GR-01 | B5: Avena | C5: AV | D5: 0.556 | E5: Grano fino | F5: Alta superficie específica
A6: GR-02 | B6: Maíz | C6: MA | D6: 0.802 | E6: Grano grueso | F6: Mayor resistencia a hidratación
A7: GR-03 | B7: Trigo | C7: TR | D7: 0.75 | E7: Grano medio | F7: Uso general
A8: GR-04 | B8: Centeno | C8: CE | D8: 0.7 | E8: Grano medio | F8: Buena retención
A9: GR-05 | B9: Sorgo | C9: SO | D9: 0.75 | E9: Grano medio | F9: Alternativa económica
A11: 🧪 AGENTES DESCONTAMINANTES
A12: ID | B12: Nombre | C12: Conc. Default (%) | D12: Tipo | E12: Notas
A13: AG-01 | B13: ÁCIDO PERACÉTICO | C13: 5 | D13: Oxidativo | E13: Descontaminante oxidativo
A14: AG-02 | B14: HIPOCLORITO DE SODIO | C14: 1 | D14: Clorado | E14: Blanqueador desinfectante
A15: AG-03 | B15: PERÓXIDO DE HIDRÓGENO | C15: 3 | D15: Oxidativo | E15: Oxidante fuerte
A17: 📦 ADITIVOS
A18: ID | B18: Nombre | C18: Tipo | D18: Función | E18: Notas
A19: AD-01 | B19: CaSO4 (Yeso) | C19: Estructurante | D19: Mejora aireación | E19: Uso común 1-3%
A20: AD-02 | B20: Carbonato de Calcio | C20: Corrector pH | D20: Alcalinizante | E20: Sube pH
A21: AD-03 | B21: Gesso | C21: Estructurante | D21: Similar al yeso | E21: Alternativa
A22: AD-04 | B22: Tiza | C22: Estructurante | D22: Fuente de calcio | E22: Económica
A24: 🫙 CONFIGURACIÓN FRASCOS
A25: ID | B25: Tipo Frasco | C25: Capacidad (ml) | D25: Carga Útil (ml)
A26: FR-01 | B26: Frasco 660ml | C26: 660 | D26: 500
A27: FR-02 | B27: Frasco 1000ml | C27: 1000 | D27: 800
A28: FR-03 | B28: Bolsa 1.5L | C28: 1500 | D28: 1200

Sheet Calculadora
A1: 🌽 CALCULADORA DE SUSTRATOS
A3: 📋 INFORMACIÓN DEL LOTE
A4: ID Lote: | B4: GR273 | D4: Masa Total (g): | E4: =E17 -> 2406
A5: Nombre Mezcla: | B5: MA100COCCION | D5: Volumen Total (ml): | E5: =C17 -> 3000
A6: Fecha: | B6: 2026-03-27 | D6: Densidad Promedio: | E6: =IF(E5=0,"",E4/E5) -> 0.802
A7: Versión: | B7: v1
A9: 🌾 CT - CARACTERIZACIÓN DE COMPONENTES
A10: Ingrese volumen (ml), la masa se calcula automáticamente con la densidad del grano
A11: # | B11: Grano | C11: Volumen (ml) | D11: Densidad (g/ml) | E11: Masa (g) | F11: % del Total | G11: Notas
A12: 1 | B12: Maíz | C12: 3000 | D12: =IF(B12="","",VLOOKUP(B12,Biblioteca!$B$5:$D$9,3,FALSE)) -> 0.802 | E12: =IF(OR(C12="",D12=""),"",C12*D12) -> 2406 | F12: =IF(E12="","",E12/E$17) -> 1
A13: 2 | D13: =IF(B13="","",VLOOKUP(B13,Biblioteca!$B$5:$D$9,3,FALSE)) | E13: =IF(OR(C13="",D13=""),"",C13*D13) | F13: =IF(E13="","",E13/E$17)
A14: 3 | D14: =IF(B14="","",VLOOKUP(B14,Biblioteca!$B$5:$D$9,3,FALSE)) | E14: =IF(OR(C14="",D14=""),"",C14*D14) | F14: =IF(E14="","",E14/E$17)
A15: 4 | D15: =IF(B15="","",VLOOKUP(B15,Biblioteca!$B$5:$D$9,3,FALSE)) | E15: =IF(OR(C15="",D15=""),"",C15*D15) | F15: =IF(E15="","",E15/E$17)
A16: 5 | D16: =IF(B16="","",VLOOKUP(B16,Biblioteca!$B$5:$D$9,3,FALSE)) | E16: =IF(OR(C16="",D16=""),"",C16*D16) | F16: =IF(E16="","",E16/E$17)
A17: TOTAL | C17: =SUM(C12:C16) -> 3000 | E17: =SUM(E12:E16) -> 2406 | F17: =SUM(F12:F16) -> 1
A19: 🧪 DC - DESCONTAMINACIÓN
A20: Volumen Solución (L): | B20: 4 | D20: 📊 RESULTADOS DC
A21: Agente: | B21: ÁCIDO PERACÉTICO | D21: Concentración Final (%): | E21: =IF(OR(B20="",B22="",B23=""),"",((B23*B22)/(B20*1000))*100) -> 7.5
A22: Conc. Agente (%): | B22: =IF(B21="","",VLOOKUP(B21,Biblioteca!$B$13:$C$15,2,FALSE)) -> 5 | D22: Agua necesaria (L): | E22: =IF(B20="","",B20-(B23/1000)) -> 3.94
A23: Vol. Agente (ml): | B23: 60 | D23: Proporción Agente:Agua: | E23: =IF(OR(B23="",E22=""),"",CONCATENATE("1:",ROUND(E22*1000/B23,0))) -> 1:66
A24: Tiempo (min): | B24: 60
A25: Temperatura: | B25: AMBIENTE
A26: Agitación: | B26: PASIVA
A28: 💧 HM - HIDRATACIÓN / MÉTODO
A29: Modo: | B29: coccion | D29: Notas:
A30: Método: | B30: INMERSION DIRECTA EN AGUA HIRVIENDO
A31: Agitación: | B31: PASIVA
A32: Resultado: | B32: ok
A33: 📝 ETAPAS DEL PROCESO
A34: Paso | B34: Tipo | C34: Tiempo | D34: Unidad | E34: Notas
A35: 1 | B35: coccion | C35: 10 | D35: min | E35: INMERSION DIRECTA EN AGUA HIRVIENDO
A36: 2 | B36: coccion | C36: 15 | D36: min | E36: Fuego mínimo con agitación pasiva
A37: 3 | B37: coccion | C37: 15 | D37: min | E37: Fuego mínimo
A38: 4 | B38: coccion | C38: 15 | D38: min | E38: Fuego mínimo
A39: 5 | B39: espera | C39: 30 | D39: min | E39: Al enfriarse el maíz absorbe más agua
A40: TIEMPO TOTAL: | C40: =SUMIF(D35:D39,"min",C35:C39)+SUMIF(D35:D39,"h",C35:C39)*60 -> 85 | D40: min
A42: 📊 DM - DINÁMICA DE MASAS
A43: Masa Seca (g): | B43: =E17 -> 2406 | D43: 📈 MÉTRICAS CALCULADAS
A44: Masa Hidratada (g): | B44: 5406 | D44: Agua Absorbida (g): | E44: =IF(OR(B43="",B44=""),"",B44-B43) -> 3000
A45: Densidad Hidratada (g/L): | B45: 901 | D45: Retención (%): | E45: =IF(OR(B43=0,B43="",E44=""),"",E44/B43*100) -> 124.68828
...

Sheet Registros
A1: 📋 REGISTRO HISTÓRICO DE LOTES
A2: Copie y pegue los datos de cada lote completado aquí para mantener un registro histórico
A4: ID Lote | B4: Fecha | C4: Mezcla | D4: Versión | E4: Vol. Total (ml) | F4: Masa Total (g) | G4: Componentes | H4: Agente DC | I4: Conc. DC (%) | J4: Modo HM | K4: Tiempo HM (min) | L4: Masa Hidr. (g) | M4: Retención (%) | N4: Expansión (%) | O4: Cant. Frascos | P4: Tiempo ES (min) | Q4: Resultado | R4: Notas
A56: 📊 ESTADÍSTICAS
A57: Total Lotes: | B57: =COUNTA(A5:A54) -> 0 | E57: Promedio Retención: | F57: =_xlfn.IFERROR(AVERAGE(M5:M54),"") | I57: Promedio Frascos: | J57: =_xlfn.IFERROR(AVERAGE(O5:O54),"")
